Workbook

Sheet Executive Summary
A1: Tractor Supply Company (TSCO) - Financial Analysis
A3: Current Market Price (Live): | B3: 31.219999
A4: Implied Target Price (Blended DCF): | B4: ='DCF Valuation'!C55
A6: Recommendation: | B6: =IF(B4 > B3*1.1, "STRONG BUY", IF(B4 > B3, "BUY", IF(B4 < B3*0.9, "SELL", "HOLD")))
A8: Key Investment Drivers:
A9: 1. Top-Line Growth: Revenue projected at a conservative 5.0% CAGR through 2030E.
A10: 2. Margin Stability: Gross margins modeled flat at 35.0% with SG&A optimized at 23.0%.
A11: 3. Valuation Derivation: Utilized CAPM to structure a dynamic WACC, cross-checked with a 14.0x EV/EBITDA exit multiple.
A13: Simplifying Assumptions & Limitations:
A14: 1. Share Count vs. Buybacks: Modeled $600M annual share repurchases as a cash outflow, but held shares outstanding constant for valuation to avoid artificial EPS accretion.
A15: 2. Aggressive Deleverage: Modeled a 100% cash sweep for balances over $200M, preventing cash accumulation on the Balance Sheet in favor of zero-debt.

Sheet Income Statement
A1: Line Item | B1: 2021 | C1: 2022 | D1: 2023 | E1: 2024 | F1: 2025 | G1: 2026E | H1: 2027E | I1: 2028E | J1: 2029E | K1: 2030E
A2: Total Revenue | C2: 14204717000 | D2: 14555741000 | E2: 14883231000 | F2: 15524046000 | G2: =F2*(1+G12) | H2: =G2*(1+H12) | I2: =H2*(1+I12) | J2: =I2*(1+J12) | K2: =J2*(1+K12)
A3: Cost Of Revenue | C3: 9232513000 | D3: 9327522000 | E3: 9486674000 | F3: 9869538000 | G3: =G2*(1-G13) | H3: =H2*(1-H13) | I3: =I2*(1-I13) | J3: =J2*(1-J13) | K3: =K2*(1-K13)
A4: Gross Profit | C4: 4972204000 | D4: 5228219000 | E4: 5396557000 | F4: 5654508000 | G4: =G2-G3 | H4: =H2-H3 | I4: =I2-I3 | J4: =J2-J3 | K4: =K2-K3
A5: Selling General And Administration | C5: 3194199000 | D5: 3356258000 | E5: 3481863000 | F5: 3693108000 | G5: =G2*G14 | H5: =H2*H14 | I5: =I2*I14 | J5: =J2*J14 | K5: =K2*K14
A6: Operating Income | C6: 1434943000 | D6: 1478912000 | E6: 1467532000 | F6: 1467389000 | G6: =G4-G5 | H6: =H4-H5 | I6: =I4-I5 | J6: =J4-J5 | K6: =K4-K5
A7: Interest Expense | C7: 30633000 | D7: 46510000 | E7: 54592000 | F7: 69144000 | G7: ='Debt Schedule'!G14*'Debt Schedule'!G4 | H7: ='Debt Schedule'!H14*'Debt Schedule'!H4 | I7: ='Debt Schedule'!I14*'Debt Schedule'!I4 | J7: ='Debt Schedule'!J14*'Debt Schedule'!J4 | K7: ='Debt Schedule'!K14*'Debt Schedule'!K4
A8: Tax Provision | C8: 315598000 | D8: 325176000 | E8: 311700000 | F8: 302158000 | G8: =(G6-G7)*G15 | H8: =(H6-H7)*H15 | I8: =(I6-I7)*I15 | J8: =(J6-J7)*J15 | K8: =(K6-K7)*K15
A9: Net Income | C9: 1088712000 | D9: 1107226000 | E9: 1101240000 | F9: 1096087000 | G9: =G6-G7-G8 | H9: =H6-H7-H8 | I9: =I6-I7-I8 | J9: =J6-J7-J8 | K9: =K6-K7-K8
A11: ASSUMPTIONS
A12: Revenue Growth (%) | G12: 0.05 | H12: 0.05 | I12: 0.05 | J12: 0.05 | K12: 0.05
A13: Gross Margin (%) | G13: 0.35 | H13: 0.35 | I13: 0.35 | J13: 0.35 | K13: 0.35
A14: SG&A Margin (%) | G14: 0.23 | H14: 0.23 | I14: 0.23 | J14: 0.23 | K14: 0.23
A15: Effective Tax Rate (%) | G15: 0.24 | H15: 0.24 | I15: 0.24 | J15: 0.24 | K15: 0.24

Sheet Balance Sheet
A1: Line Item | B1: 2021 | C1: 2022 | D1: 2023 | E1: 2024 | F1: 2025 | G1: 2026E | H1: 2027E | I1: 2028E | J1: 2029E | K1: 2030E
A2: Cash And Cash Equivalents | C2: 202502000 | D2: 397071000 | E2: 251491000 | F2: 194109000 | G2: =F2+'Cash Flow Statement'!G12 | H2: =G2+'Cash Flow Statement'!H12 | I2: =H2+'Cash Flow Statement'!I12 | J2: =I2+'Cash Flow Statement'!J12 | K2: =J2+'Cash Flow Statement'!K12
A3: Receivables | C3: 0 | D3: 2461000 | E3: 21635000 | F3: 27045000 | G3: ='Income Statement'!G2*G15 | H3: ='Income Statement'!H2*H15 | I3: ='Income Statement'!I2*I15 | J3: ='Income Statement'!J2*J15 | K3: ='Income Statement'!K2*K15
A4: Inventory | C4: 2709597000 | D4: 2645854000 | E4: 2840177000 | F4: 3084086000 | G4: ='Income Statement'!G3*G16 | H4: ='Income Statement'!H3*H16 | I4: ='Income Statement'!I3*I16 | J4: ='Income Statement'!J3*J16 | K4: ='Income Statement'!K3*K16
A5: Net PPE | C5: 5037417000 | D5: 5579155000 | E5: 6142880000 | F5: 6964971000 | G5: =F5-'Cash Flow Statement'!G6-'Cash Flow Statement'!G3 | H5: =G5-'Cash Flow Statement'!H6-'Cash Flow Statement'!H3 | I5: =H5-'Cash Flow Statement'!I6-'Cash Flow Statement'!I3 | J5: =I5-'Cash Flow Statement'!J6-'Cash Flow Statement'!J3 | K5: =J5-'Cash Flow Statement'!K6-'Cash Flow Statement'!K3
A6: Accounts Payable | C6: 1398288000 | D6: 1179803000 | E6: 1236177000 | F6: 1390833000 | G6: ='Income Statement'!G3*G17 | H6: ='Income Statement'!H3*H17 | I6: ='Income Statement'!I3*I17 | J6: ='Income Statement'!J3*J17 | K6: ='Income Statement'!K3*K17
A7: Current Accrued Expenses | C7: 498575000 | D7: 533029000 | E7: 581971000 | F7: 653482000 | G7: =F7 | H7: =G7 | I7: =H7 | J7: =I7 | K7: =J7
A8: Long Term Debt | C8: 1164100000 | D8: 1729000000 | E8: 1832000000 | F8: 1765000000 | G8: ='Debt Schedule'!G17 | H8: ='Debt Schedule'!H17 | I8: ='Debt Schedule'!I17 | J8: ='Debt Schedule'!J17 | K8: ='Debt Schedule'!K17
A9: Common Stock | C9: 1415000 | D9: 7093000 | E9: 7116000 | F9: 7128000 | G9: =F9 | H9: =G9 | I9: =H9 | J9: =I9 | K9: =J9
A10: Retained Earnings | C10: 5624352000 | D10: 6281959000 | E10: 6910707000 | F10: 7519125000 | G10: =F10+'Income Statement'!G9+'Cash Flow Statement'!G9 | H10: =G10+'Income Statement'!H9+'Cash Flow Statement'!H9 | I10: =H10+'Income Statement'!I9+'Cash Flow Statement'!I9 | J10: =I10+'Income Statement'!J9+'Cash Flow Statement'!J9 | K10: =J10+'Income Statement'!K9+'Cash Flow Statement'!K9
A11: Treasury Stock | C11: 4855909000 | D11: 5458855000 | E11: 6025238000 | F11: 6386229000 | G11: =F11-'Cash Flow Statement'!G10 | H11: =G11-'Cash Flow Statement'!H10 | I11: =H11-'Cash Flow Statement'!I10 | J11: =I11-'Cash Flow Statement'!J10 | K11: =J11-'Cash Flow Statement'!K10
A12: Other Net Historicals (Plug) | B12: =SUM(B2:B5)-(SUM(B6:B10)-B11) | C12: =SUM(C2:C5)-(SUM(C6:C10)-C11) | D12: =SUM(D2:D5)-(SUM(D6:D10)-D11) | E12: =SUM(E2:E5)-(SUM(E6:E10)-E11) | F12: =SUM(F2:F5)-(SUM(F6:F10)-F11) | G12: =F12 | H12: =G12 | I12: =H12 | J12: =I12 | K12: =J12
A14: WORKING CAPITAL ASSUMPTIONS
A15: Receivables (% of Revenue) | G15: 0.015 | H15: 0.015 | I15: 0.015 | J15: 0.015 | K15: 0.015
A16: Inventory (% of COGS) | G16: 0.25 | H16: 0.25 | I16: 0.25 | J16: 0.25 | K16: 0.25
A17: Payables (% of COGS) | G17: 0.12 | H17: 0.12 | I17: 0.12 | J17: 0.12 | K17: 0.12
A20: MODEL AUDIT CHECK | G20: =IF(ROUND(SUM(G2:G5)-(SUM(G6:G10)-G11+G12), 0)=0, "OK - BALANCED", "ERROR: " & SUM(G2:G5)-(SUM(G6:G10)-G11+G12)) | H20: =IF(ROUND(SUM(H2:H5)-(SUM(H6:H10)-H11+H12), 0)=0, "OK - BALANCED", "ERROR: " & SUM(H2:H5)-(SUM(H6:H10)-H11+H12)) | I20: =IF(ROUND(SUM(I2:I5)-(SUM(I6:I10)-I11+I12), 0)=0, "OK - BALANCED", "ERROR: " & SUM(I2:I5)-(SUM(I6:I10)-I11+I12)) | J20: =IF(ROUND(SUM(J2:J5)-(SUM(J6:J10)-J11+J12), 0)=0, "OK - BALANCED", "ERROR: " & SUM(J2:J5)-(SUM(J6:J10)-J11+J12)) | K20: =IF(ROUND(SUM(K2:K5)-(SUM(K6:K10)-K11+K12), 0)=0, "OK - BALANCED", "ERROR: " & SUM(K2:K5)-(SUM(K6:K10)-K11+K12))

Sheet Cash Flow Statement
A1: Line Item | B1: 2021 | C1: 2022 | D1: 2023 | E1: 2024 | F1: 2025 | G1: 2026E | H1: 2027E | I1: 2028E | J1: 2029E | K1: 2030E
A2: Net Income From Continuing Operations | C2: 1088712000 | D2: 1107226000 | E2: 1101240000 | F2: 1096087000 | G2: ='Income Statement'!G9 | H2: ='Income Statement'!H9 | I2: ='Income Statement'!I9 | J2: ='Income Statement'!J9 | K2: ='Income Statement'!K9
A3: Depreciation And Amortization | C3: 343062000 | D3: 393049000 | E3: 447162000 | F3: 494011000 | G3: ='Income Statement'!G2*G15 | H3: ='Income Statement'!H2*H15 | I3: ='Income Statement'!I2*I15 | J3: ='Income Statement'!J2*J15 | K3: ='Income Statement'!K2*K15
A4: Change In Working Capital | C4: -182478000 | D4: -181416000 | E4: -90832000 | F4: 19889000 | G4: =('Balance Sheet'!F3-'Balance Sheet'!G3)+('Balance Sheet'!F4-'Balance Sheet'!G4)+('Balance Sheet'!G6-'Balance Sheet'!F6) | H4: =('Balance Sheet'!G3-'Balance Sheet'!H3)+('Balance Sheet'!G4-'Balance Sheet'!H4)+('Balance Sheet'!H6-'Balance Sheet'!G6) | I4: =('Balance Sheet'!H3-'Balance Sheet'!I3)+('Balance Sheet'!H4-'Balance Sheet'!I4)+('Balance Sheet'!I6-'Balance Sheet'!H6) | J4: =('Balance Sheet'!I3-'Balance Sheet'!J3)+('Balance Sheet'!I4-'Balance Sheet'!J4)+('Balance Sheet'!J6-'Balance Sheet'!I6) | K4: =('Balance Sheet'!J3-'Balance Sheet'!K3)+('Balance Sheet'!J4-'Balance Sheet'!K4)+('Balance Sheet'!K6-'Balance Sheet'!J6)
A5: Operating Cash Flow | C5: 1356979000 | D5: 1334033000 | E5: 1420835000 | F5: 1635259000 | G5: =SUM(G2:G4) | H5: =SUM(H2:H4) | I5: =SUM(I2:I4) | J5: =SUM(J2:J4) | K5: =SUM(K2:K4)
A6: Capital Expenditure | C6: -773369000 | D6: -753883000 | E6: -784047000 | F6: -894770000 | G6: ='Income Statement'!G2*G16 | H6: ='Income Statement'!H2*H16 | I6: ='Income Statement'!I2*I16 | J6: ='Income Statement'!J2*J16 | K6: ='Income Statement'!K2*K16
A7: Investing Cash Flow | C7: -1093726000 | D7: -653069000 | E7: -643918000 | F7: -778578000 | G7: =G6 | H7: =H6 | I7: =I6 | J7: =J6 | K7: =K6
A8: Repayment Of Debt | C8: -836058000 | D8: -1199808000 | E8: -689787000 | F8: -3197819000 | G8: =-('Debt Schedule'!G15+'Debt Schedule'!G16) | H8: =-('Debt Schedule'!H15+'Debt Schedule'!H16) | I8: =-('Debt Schedule'!I15+'Debt Schedule'!I16) | J8: =-('Debt Schedule'!J15+'Debt Schedule'!J16) | K8: =-('Debt Schedule'!K15+'Debt Schedule'!K16)
A9: Cash Dividends Paid | C9: -409603000 | D9: -449620000 | E9: -472492000 | F9: -487669000 | G9: -500000000 | H9: -500000000 | I9: -500000000 | J9: -500000000 | K9: -500000000
A10: Repurchase Of Capital Stock | C10: -728655000 | D10: -618635000 | E10: -584575000 | F10: -377138000 | G10: -600000000 | H10: -600000000 | I10: -600000000 | J10: -600000000 | K10: -600000000
A11: Financing Cash Flow | C11: -938781000 | D11: -486395000 | E11: -922497000 | F11: -914063000 | G11: =SUM(G8:G10) | H11: =SUM(H8:H10) | I11: =SUM(I8:I10) | J11: =SUM(J8:J10) | K11: =SUM(K8:K10)
A12: Changes In Cash | C12: -675528000 | D12: 194569000 | E12: -145580000 | F12: -57382000 | G12: =G5+G7+G11 | H12: =H5+H7+H11 | I12: =I5+I7+I11 | J12: =J5+J7+J11 | K12: =K5+K7+K11
A14: CASH FLOW ASSUMPTIONS
A15: D&A (% of Revenue) | G15: 0.025 | H15: 0.025 | I15: 0.025 | J15: 0.025 | K15: 0.025
A16: CapEx (% of Revenue) | G16: -0.04 | H16: -0.04 | I16: -0.04 | J16: -0.04 | K16: -0.04

Sheet Debt Schedule
A1: DEBT SCHEDULE | G1: 2026E | H1: 2027E | I1: 2028E | J1: 2029E | K1: 2030E
A2: ASSUMPTIONS
A3: Minimum Cash Balance | G3: 200000000 | H3: 200000000 | I3: 200000000 | J3: 200000000 | K3: 200000000
A4: Interest Rate on Debt | G4: 0.045 | H4: 0.045 | I4: 0.045 | J4: 0.045 | K4: 0.045
A6: CASH AVAILABLE FOR DEBT SERVICE (CADS)
A7: Beginning Cash Balance | G7: ='Balance Sheet'!F2 | H7: ='Balance Sheet'!G2 | I7: ='Balance Sheet'!H2 | J7: ='Balance Sheet'!I2 | K7: ='Balance Sheet'!J2
A8: Operating Cash Flow | G8: ='Cash Flow Statement'!G5 | H8: ='Cash Flow Statement'!H5 | I8: ='Cash Flow Statement'!I5 | J8: ='Cash Flow Statement'!J5 | K8: ='Cash Flow Statement'!K5
A9: Investing Cash Flow | G9: ='Cash Flow Statement'!G7 | H9: ='Cash Flow Statement'!H7 | I9: ='Cash Flow Statement'!I7 | J9: ='Cash Flow Statement'!J7 | K9: ='Cash Flow Statement'!K7
A10: Dividends & Repurchases | G10: ='Cash Flow Statement'!G9+'Cash Flow Statement'!G10 | H10: ='Cash Flow Statement'!H9+'Cash Flow Statement'!H10 | I10: ='Cash Flow Statement'!I9+'Cash Flow Statement'!I10 | J10: ='Cash Flow Statement'!J9+'Cash Flow Statement'!J10 | K10: ='Cash Flow Statement'!K9+'Cash Flow Statement'!K10
A11: CADS | G11: =SUM(G7:G10) | H11: =SUM(H7:H10) | I11: =SUM(I7:I10) | J11: =SUM(J7:J10) | K11: =SUM(K7:K10)
A13: LONG TERM DEBT ROLL-FORWARD
A14: Beginning Debt Balance | G14: ='Balance Sheet'!F8 | H14: =G17 | I14: =H17 | J14: =I17 | K14: =J17
A15: Less: Mandatory Repayment | G15: 0 | H15: 0 | I15: 0 | J15: 0 | K15: 0
A16: Less: Cash Sweep (Optional) | G16: =MIN(G14, MAX(0, G11-G3)) | H16: =MIN(H14, MAX(0, H11-H3)) | I16: =MIN(I14, MAX(0, I11-I3)) | J16: =MIN(J14, MAX(0, J11-J3)) | K16: =MIN(K14, MAX(0, K11-K3))
A17: Ending Debt Balance | G17: =G14-G15-G16 | H17: =H14-H15-H16 | I17: =I14-I15-I16 | J17: =J14-J15-J16 | K17: =K14-K15-K16

Sheet DCF Valuation
A1: DISCOUNTED CASH FLOW VALUATION | G1: 2026E | H1: 2027E | I1: 2028E | J1: 2029E | K1: 2030E
A3: WACC DERIVATION (CAPM)
A4: Risk Free Rate (10-Yr Treasury) | G4: 0.050419998
A5: Company Beta (Damodaran Industry Proxy) | G5: 1.05
A6: Equity Risk Premium | G6: 0.055
A7: Cost of Equity (Ke) | G7: =G4+(G5*G6)
A8: After-Tax Cost of Debt (Kd) | G8: ='Debt Schedule'!G4*(1-'Income Statement'!G15)
A9: Current Share Price (Live) | G9: 31.219999
A10: Shares Outstanding (Raw) | G10: 521040137
A11: Market Value of Equity (E) | G11: =G9*G10
A12: Market Value of Debt (D) | G12: ='Balance Sheet'!F8
A13: Total Capital (V) | G13: =G11+G12
A14: Weight of Equity (E/V) | G14: =G11/G13
A15: Weight of Debt (D/V) | G15: =G12/G13
A16: Calculated WACC | G16: =(G14*G7)+(G15*G8)
A17: Terminal Growth Rate | G17: 0.02
A18: Exit Multiple (EV/EBITDA) | G18: 14
A19: Discount Period | G19: 1 | H19: 2 | I19: 3 | J19: 4 | K19: 5
A21: UNLEVERED FREE CASH FLOW
A22: EBIT | G22: ='Income Statement'!G6 | H22: ='Income Statement'!H6 | I22: ='Income Statement'!I6 | J22: ='Income Statement'!J6 | K22: ='Income Statement'!K6
A23: Less: Taxes on EBIT | G23: =G22*'Income Statement'!G15 | H23: =H22*'Income Statement'!H15 | I23: =I22*'Income Statement'!I15 | J23: =J22*'Income Statement'!J15 | K23: =K22*'Income Statement'!K15
A24: Net Operating Profit After Tax (NOPAT) | G24: =G22-G23 | H24: =H22-H23 | I24: =I22-I23 | J24: =J22-J23 | K24: =K22-K23
A25: Plus: D&A | G25: ='Cash Flow Statement'!G3 | H25: ='Cash Flow Statement'!H3 | I25: ='Cash Flow Statement'!I3 | J25: ='Cash Flow Statement'!J3 | K25: ='Cash Flow Statement'!K3
A26: Less: Capital Expenditures | G26: ='Cash Flow Statement'!G6 | H26: ='Cash Flow Statement'!H6 | I26: ='Cash Flow Statement'!I6 | J26: ='Cash Flow Statement'!J6 | K26: ='Cash Flow Statement'!K6
A27: Less: Change in Working Capital | G27: ='Cash Flow Statement'!G4 | H27: ='Cash Flow Statement'!H4 | I27: ='Cash Flow Statement'!I4 | J27: ='Cash Flow Statement'!J4 | K27: ='Cash Flow Statement'!K4
A28: Unlevered Free Cash Flow (UFCF) | G28: =G24+G25+G26+G27 | H28: =H24+H25+H26+H27 | I28: =I24+I25+I26+I27 | J28: =J24+J25+J26+J27 | K28: =K24+K25+K26+K27
A30: PRESENT VALUE OF CASH FLOWS
A31: Discount Factor | G31: =(1+$G$16)^G19 | H31: =(1+$G$16)^H19 | I31: =(1+$G$16)^I19 | J31: =(1+$G$16)^J19 | K31: =(1+$G$16)^K19
A32: Present Value of UFCF | G32: =G28/G31 | H32: =H28/H31 | I32: =I28/I31 | J32: =J28/J31 | K32: =K28/K31
A34: TERMINAL VALUE - GORDON GROWTH
A35: Terminal Value | C35: =(K28*(1+G17))/(G16-G17)
A36: PV of Terminal Value | C36: =C35/K31
A37: PV of Stage 1 Cash Flows | C37: =SUM(G32:K32)
A38: Enterprise Value | C38: =C36+C37
A39: Plus: Current Cash | C39: ='Balance Sheet'!F2
A40: Less: Current Debt | C40: ='Balance Sheet'!F8
A41: Equity Value | C41: =C38+C39-C40
A42: Implied Price (Perpetuity Method) | C42: =C41/G10
A44: TERMINAL VALUE - EXIT MULTIPLE
A45: Final Year EBITDA | C45: =K22+K25
...
